"""Config flow for GivEnergy integration."""
from __future__ import annotations

from typing import Any

import async_timeout
import voluptuous as vol

from homeassistant import config_entries
from homeassistant.core import HomeAssistant
from homeassistant.data_entry_flow import FlowResult
from homeassistant.exceptions import HomeAssistantError

from .const import CONF_HOST, DOMAIN, LOGGER
from .givenergy import GivEnergy

STEP_USER_DATA_SCHEMA = vol.Schema({vol.Required(CONF_HOST): str})


async def validate_input(hass: HomeAssistant, data: dict[str, Any]) -> dict[str, Any]:
    """Validate the user input allows us to connect.

    Data has the keys from STEP_USER_DATA_SCHEMA with values provided by the user.
    """
    try:
        givenergy = GivEnergy(data[CONF_HOST])
        async with async_timeout.timeout(10):
            await hass.async_add_executor_job(givenergy.fetch_data)

        return {"title": "Solar Inverter", "host": data[CONF_HOST]}
    except Exception:  # pylint: disable=broad-except
        raise CannotConnect from Exception


class ConfigFlow(config_entries.ConfigFlow, domain=DOMAIN):
    """Handle a config flow for GivEnergy."""

    VERSION = 1

    async def async_step_user(
        self, user_input: dict[str, Any] | None = None
    ) -> FlowResult:
        """Handle the initial step."""
        if user_input is None:
            return self.async_show_form(
                step_id="user", data_schema=STEP_USER_DATA_SCHEMA
            )

        errors = {}

        try:
            info = await validate_input(self.hass, user_input)
        except CannotConnect:
            errors["base"] = "cannot_connect"
        except Exception:  # pylint: disable=broad-except
            LOGGER.exception("Unexpected exception")
            errors["base"] = "unknown"
        else:
            return self.async_create_entry(title=info["title"], data=user_input)

        return self.async_show_form(
            step_id="user", data_schema=STEP_USER_DATA_SCHEMA, errors=errors
        )


class CannotConnect(HomeAssistantError):
    """Error to indicate we cannot connect."""
